2024-06-24 21:51:15,963 INFO    StreamThr :11956 [internal.py:wandb_internal():85] W&B internal server running at pid: 11956, started at: 2024-06-24 21:51:15.963348
2024-06-24 21:51:15,965 DEBUG   HandlerThread:11956 [handler.py:handle_request():158] handle_request: status
2024-06-24 21:51:15,968 INFO    WriterThread:11956 [datastore.py:open_for_write():87] open: C:\Users\mehdi\IMDB-MIR\Logic\core\finetuner\wandb\run-20240624_215115-9v7yd4gl\run-9v7yd4gl.wandb
2024-06-24 21:51:15,969 DEBUG   SenderThread:11956 [sender.py:send():378] send: header
2024-06-24 21:51:16,015 DEBUG   SenderThread:11956 [sender.py:send():378] send: run
2024-06-24 21:51:16,543 ERROR   SenderThread:11956 [internal_api.py:execute():344] 403 response executing GraphQL.
2024-06-24 21:51:16,543 ERROR   SenderThread:11956 [internal_api.py:execute():345] 
<html><head>
<meta http-equiv="content-type" content="text/html;charset=utf-8">
<title>403 Forbidden</title>
</head>
<body text=#000000 bgcolor=#ffffff>
<h1>Error: Forbidden</h1>
<h2>Your client does not have permission to get URL <code>/graphql</code> from this server.</h2>
<h2></h2>
</body></html>

2024-06-24 21:51:16,543 ERROR   SenderThread:11956 [sender.py:send_run():970] It appears that you do not have permission to access the requested resource. Please reach out to the project owner to grant you access. If you have the correct permissions, verify that there are no issues with your networking setup.(Error 403: Forbidden)
Traceback (most recent call last):
  File "C:\Users\mehdi\IMDB-MIR\.venv\Lib\site-packages\wandb\sdk\lib\retry.py", line 131, in __call__
    result = self._call_fn(*args, **kwargs)
             ^^^^^^^^^^^^^^^^^^^^^^^^^^^^^^
  File "C:\Users\mehdi\IMDB-MIR\.venv\Lib\site-packages\wandb\sdk\internal\internal_api.py", line 340, in execute
    return self.client.execute(*args, **kwargs)  # type: ignore
           ^^^^^^^^^^^^^^^^^^^^^^^^^^^^^^^^^^^^
  File "C:\Users\mehdi\IMDB-MIR\.venv\Lib\site-packages\wandb\vendor\gql-0.2.0\wandb_gql\client.py", line 52, in execute
    result = self._get_result(document, *args, **kwargs)
             ^^^^^^^^^^^^^^^^^^^^^^^^^^^^^^^^^^^^^^^^^^^
  File "C:\Users\mehdi\IMDB-MIR\.venv\Lib\site-packages\wandb\vendor\gql-0.2.0\wandb_gql\client.py", line 60, in _get_result
    return self.transport.execute(document, *args, **kwargs)
           ^^^^^^^^^^^^^^^^^^^^^^^^^^^^^^^^^^^^^^^^^^^^^^^^^
  File "C:\Users\mehdi\IMDB-MIR\.venv\Lib\site-packages\wandb\sdk\lib\gql_request.py", line 59, in execute
    request.raise_for_status()
  File "C:\Users\mehdi\IMDB-MIR\.venv\Lib\site-packages\requests\models.py", line 1024, in raise_for_status
    raise HTTPError(http_error_msg, response=self)
requests.exceptions.HTTPError: 403 Client Error: Forbidden for url: https://api.wandb.ai/graphql

During handling of the above exception, another exception occurred:

Traceback (most recent call last):
  File "C:\Users\mehdi\IMDB-MIR\.venv\Lib\site-packages\wandb\sdk\internal\sender.py", line 968, in send_run
    server_run = self._init_run(run, config_value_dict)
                 ^^^^^^^^^^^^^^^^^^^^^^^^^^^^^^^^^^^^^^
  File "C:\Users\mehdi\IMDB-MIR\.venv\Lib\site-packages\wandb\sdk\internal\sender.py", line 1013, in _init_run
    server_run, inserted, server_messages = self._api.upsert_run(
                                            ^^^^^^^^^^^^^^^^^^^^^
  File "C:\Users\mehdi\IMDB-MIR\.venv\Lib\site-packages\wandb\apis\normalize.py", line 73, in wrapper
    raise err
  File "C:\Users\mehdi\IMDB-MIR\.venv\Lib\site-packages\wandb\apis\normalize.py", line 41, in wrapper
    return func(*args, **kwargs)
           ^^^^^^^^^^^^^^^^^^^^^
  File "C:\Users\mehdi\IMDB-MIR\.venv\Lib\site-packages\wandb\sdk\internal\internal_api.py", line 2131, in upsert_run
    self.server_settings_introspection()
  File "C:\Users\mehdi\IMDB-MIR\.venv\Lib\site-packages\wandb\apis\normalize.py", line 73, in wrapper
    raise err
  File "C:\Users\mehdi\IMDB-MIR\.venv\Lib\site-packages\wandb\apis\normalize.py", line 41, in wrapper
    return func(*args, **kwargs)
           ^^^^^^^^^^^^^^^^^^^^^
  File "C:\Users\mehdi\IMDB-MIR\.venv\Lib\site-packages\wandb\sdk\internal\internal_api.py", line 556, in server_settings_introspection
    res = self.gql(query)
          ^^^^^^^^^^^^^^^
  File "C:\Users\mehdi\IMDB-MIR\.venv\Lib\site-packages\wandb\sdk\internal\internal_api.py", line 312, in gql
    ret = self._retry_gql(
          ^^^^^^^^^^^^^^^^
  File "C:\Users\mehdi\IMDB-MIR\.venv\Lib\site-packages\wandb\sdk\lib\retry.py", line 147, in __call__
    retry_timedelta_triggered = check_retry_fn(e)
                                ^^^^^^^^^^^^^^^^^
  File "C:\Users\mehdi\IMDB-MIR\.venv\Lib\site-packages\wandb\util.py", line 907, in no_retry_auth
    raise CommError(
wandb.errors.CommError: It appears that you do not have permission to access the requested resource. Please reach out to the project owner to grant you access. If you have the correct permissions, verify that there are no issues with your networking setup.(Error 403: Forbidden)
2024-06-24 21:51:18,580 DEBUG   HandlerThread:11956 [handler.py:handle_request():158] handle_request: shutdown
2024-06-24 21:51:18,581 INFO    HandlerThread:11956 [handler.py:finish():882] shutting down handler
2024-06-24 21:51:19,046 INFO    WriterThread:11956 [datastore.py:close():296] close: C:\Users\mehdi\IMDB-MIR\Logic\core\finetuner\wandb\run-20240624_215115-9v7yd4gl\run-9v7yd4gl.wandb
2024-06-24 21:51:19,575 INFO    SenderThread:11956 [sender.py:finish():1545] shutting down sender
